Workbook

Sheet Yr-2Approved Budget
A1: Partner: DAPTA (Development Agency for Poor and Tribal Awakening)
A2: Project Title: Ensuring food and livelihood security of indigenous and other marginalized communities(MCC) in Thakurmunda Block, Mayurbhanj, Odisha
A3: Project Location (District/State: Thakurmunda Block, Odisha
A4: Proposed project period: 1 June 2023 to 31 March 2026 | D4: PROJECT START DATE 1 JUNE -2023 END DATE 31 MARCH -2026
A5: ID | B5: Proposed Budget | C5: Unit description | D5: Year-1-2023-24 | I5: Revised Year-1 Budget (2023-24) (for 10 months) | O5: Year-1 budget Break-up | U5: Year-2-2024-25 (Initial Budget) | AA5: Approved Revised Year-2 Budget (2024-25) | AF5: Year-3 2025-26 | AK5: Total of 3 years: 2023-2026 | AO5: MCC comments (4 Jan 2023) | AP5: Remarks | AR5: Quarter-wise bifurcation of Year-2 MCC Budget
D6: Price per unit | E6: Year- 1 unit quantity | F6: Year-1 MCC Contribution | G6: Year-1 Partner or others' contribution | H6: Year- 1 Total Budgeted Amount | I6: Revised Unit Quantity | J6: Revised Unit Price | K6: MCC Revised Contribution Yr-1 | L6: Participants' contribution | M6: Total Revised Budget Yr-1 | O6: 1st Qtr. (June 23) | P6: 2nd Qtr. | Q6: 3rd Qtr. | R6: 4th Qtr. | S6: Total | U6: Price per unit | V6: Year 2 unit quantity | W6: Year-2 MCC Contribution | X6: Year-2 Partner or others' contribution | Y6: Year- 2 Total Budgeted Amount | AA6: Revised Unit price | AB6: Revised Unit quantity | AC6: MCC Revised Contribution Yr-2 | AD6: Participants'/ others contribution | AE6: Total Revised Budget Yr-2 | AF6: Price per unit | AG6: Year 3 unit quantity | AH6: Year-3 MCC Contribution | AI6: Year-3 Partner or others' contribution | AJ6: Year 3 Total Budgeted Amount | AK6: Total Proposed Quantity of 3 years | AL6: Total MCC Contribution | AM6: Total Partner or others' contribution | AN6: Total Budget of Project Period | AR6: Qtr-1 (Apr-Jun 2024) | AS6: Qtr-2 (Jul-Sept 2024) | AT6: Qtr-3 (Oct-Dec 2024) | AU6: Qtr-4 (Jan-Mar 2025) | AV6: Total MCC Budget 2024-25
A7: 1 | B7: Outcome :1 Activities | AO7: For Amy Martens: Changes made are in blue font. Justification in change in uniti price in Year 1,2 & 3 can be seen as per the calculation shown under Column B.
A8: 1.1 | B8: Baseline | C8: 0 | D8: 0 | E8: 0 | F8: 0 | G8: 0 | H8: 0 | I8: 1 | J8: 30000 | K8: =I8*J8 -> 30000 | M8: =K8+L8 -> 30000 | O8: =M8 -> 30000 | S8: =O8+P8+Q8+R8 -> 30000
A9: 1.2 | B9: Monthly PRA/ Data collection/ Village Community Meeting | S9: =O9+P9+Q9+R9 -> 0
A10: 1.2.1 | B10: Monthly Village Community Meeting (Biscuits / Snacks /per time /12 Months) @Rs.15 x 437 + 6 staff =Rs.6660/- | C10: Resource person | D10: 6660 | E10: 12 | F10: =D10*E10 -> 79920 | H10: =F10+G10 -> 79920 | I10: =443*10 -> 4430 | J10: 15 | K10: =I10*J10 -> 66450 | M10: =K10+L10 -> 66450 | O10: =443*15 -> 6645 | P10: =443*15*3 -> 19935 | Q10: =443*15*3 -> 19935 | R10: =443*15*3 -> 19935 | S10: =O10+P10+Q10+R10 -> 66450 | U10: 6660 | V10: 12 | W10: =U10*V10 -> 79920 | Y10: =W10+X10 -> 79920 | AA10: 6660 | AB10: 12 | AC10: =AA10*AB10 -> 79920 | AE10: =AC10+AD10 -> 79920 | AF10: 6660 | AG10: 12 | AH10: =AF10*AG10 -> 79920 | AJ10: =AH10+AI10 -> 79920 | AK10: =E10+V10+AG10 -> 36 | AL10: =F10+W10+AH10 -> 239760 | AM10: =G10+X10+AI10 -> 0 | AN10: =AL10+AM10 -> 239760 | AR10: 19980 | AS10: 19980 | AT10: 19980 | AU10: 19980 | AV10: =AR10+AS10+AT10+AU10 -> 79920
B11: Activities Sub Total 1.2 | D11: =SUM(D10:D10) -> 6660 | E11: =SUM(E10:E10) -> 12 | F11: =SUM(F10:F10) -> 79920 | G11: =SUM(G10:G10) -> 0 | H11: =SUM(H8:H10) -> 79920 | I11: 12 | K11: =SUM(K8:K10) -> 96450 | L11: =SUM(L10:L10) -> 0 | M11: =SUM(M8:M10) -> 96450 | O11: =SUM(O8:O10) -> 36645 | P11: =SUM(P8:P10) -> 19935 | Q11: =SUM(Q8:Q10) -> 19935 | R11: =SUM(R8:R10) -> 19935 | S11: =O11+P11+Q11+R11 -> 96450 | U11: =SUM(U10:U10) -> 6660 | V11: =SUM(V10:V10) -> 12 | W11: =SUM(W10:W10) -> 79920 | X11: =SUM(X10:X10) -> 0 | Y11: =SUM(Y10:Y10) -> 79920 | AB11: =AB10 -> 12 | AC11: =AC10 -> 79920 | AD11: =AD10 -> 0 | AE11: =AE10 -> 79920 | AF11: =AF10 -> 6660 | AG11: =AG10 -> 12 | AH11: =AH10 -> 79920 | AI11: =AI10 -> 0 | ... AO11: =AO10 -> 0 | AR11: =AR10 -> 19980 | AS11: =AS10 -> 19980 | AT11: =AT10 -> 19980 | AU11: =AU10 -> 19980 | AV11: =AR11+AS11+AT11+AU11 -> 79920
A12: 1.3 | B12: Training on Improved agriculture methods and Technology :- a) SRI (Paddy farming in row) b) Multi cropping c) Crop diversification d) Crop rotation e) Azola growing f) Seed preservation g) Seed treatment
A13: 1.3.1 | B13: Honorarium , travelling & food for resource person @Rs.2000 (above mentioned some subject will be conducted by the Project staff) | C13: Resource person | D13: 2000 | E13: 1 | F13: =D13*E13 -> 2000 | H13: =F13+G13 -> 2000 | I13: 1 | J13: 2000 | K13: =I13*J13 -> 2000 | M13: =K13+L13 -> 2000 | O13: =+M13 -> 2000 | U13: 2000 | V13: 1 | W13: =U13*V13 -> 2000 | Y13: =W13+X13 -> 2000 | AA13: 2000 | AB13: 1 | AC13: =AA13*AB13 -> 2000 | AE13: =AC13+AD13 -> 2000 | AF13: 2000 | AG13: 1 | AH13: =AF13*AG13 -> 2000 | AJ13: =AH13+AI13 -> 2000 | AK13: =E13+V13+AG13 -> 3 | AL13: =F13+W13+AH13 -> 6000 | AM13: =G13+X13+AI13 -> 0 | AN13: =AL13+AM13 -> 6000 | AP13: Mukul: Will the RP be called only once out of 4 Trainings and other trainings will be taken over by project staff? RAJU : Yes | AQ13: =2000*4 -> 8000 | AR13: 2000 | AS13: 0 | AT13: 0 | AU13: 0 | AV13: =AR13+AS13+AT13+AU13 -> 2000
A14: 1.3.2 | B14: Food for 20 participants & 6 staff @ Rs.120 x 26 Person | C14: Fooding | D14: 3360 | E14: 3 | F14: =D14*E14 -> 10080 | H14: =F14+G14 -> 10080 | I14: 26 | J14: 120 | K14: =I14*J14 -> 3120 | M14: =K14+L14 -> 3120 | O14: =+M14 -> 3120 | U14: 3360 | V14: 4 | W14: =U14*V14 -> 13440 | Y14: =W14+X14 -> 13440 | AA14: 3120 | AB14: 4 | AC14: =AA14*AB14 -> 12480 | AE14: =AC14+AD14 -> 12480 | AF14: 3360 | AG14: 3 | AH14: =AF14*AG14 -> 10080 | AJ14: =AH14+AI14 -> 10080 | AK14: =E14+V14+AG14 -> 10 | AL14: =F14+W14+AH14 -> 33600 | AM14: =G14+X14+AI14 -> 0 | AN14: =AL14+AM14 -> 33600 | AP14: Rectified the calculation | AR14: 3120 | AS14: 3120 | AT14: 3120 | AU14: 3120 | AV14: =AR14+AS14+AT14+AU14 -> 12480
A15: 1.3.3 | B15: Project village to training venue Transportation charges 20 participants x 1 Project villages @ Rs.2500/-; 2 vehicles | C15: Travelling | D15: 3500 | E15: 3 | F15: =D15*E15 -> 10500 | H15: =F15+G15 -> 10500 | I15: 2 | J15: 2500 | K15: =I15*J15 -> 5000 | M15: =K15+L15 -> 5000 | O15: =+M15 -> 5000 | U15: 3500 | V15: 4 | W15: =U15*V15 -> 14000 | Y15: =W15+X15 -> 14000 | AA15: 2500 | AB15: 8 | AC15: =AA15*AB15 -> 20000 | AE15: =AC15+AD15 -> 20000 | AF15: 3500 | AG15: 3 | AH15: =AF15*AG15 -> 10500 | AJ15: =AH15+AI15 -> 10500 | AK15: =E15+V15+AG15 -> 10 | AL15: =F15+W15+AH15 -> 35000 | AM15: =G15+X15+AI15 -> 0 | AN15: =AL15+AM15 -> 35000 | AP15: We have calculated @Rs2500 as per budget description, 2 vehicles per training. | AQ15: =2500*4*4 -> 40000 | AR15: 5000 | AS15: 5000 | AT15: 5000 | AU15: 5000 | AV15: =AR15+AS15+AT15+AU15 -> 20000
A16: 1.3.4 | B16: Arrangements & training matterials @ Rs.500/- | C16: matterials | D16: 500 | E16: 3 | F16: =D16*E16 -> 1500 | H16: =F16+G16 -> 1500 | I16: 20 | J16: 50 | K16: =I16*J16 -> 1000 | M16: =K16+L16 -> 1000 | O16: =+M16 -> 1000 | U16: 500 | V16: 4 | W16: =U16*V16 -> 2000 | Y16: =W16+X16 -> 2000 | AA16: 500 | AB16: 4 | AC16: =AA16*AB16 -> 2000 | AE16: =AC16+AD16 -> 2000 | AF16: 500 | AG16: 3 | AH16: =AF16*AG16 -> 1500 | AJ16: =AH16+AI16 -> 1500 | AK16: =E16+V16+AG16 -> 10 | AL16: =F16+W16+AH16 -> 5000 | AM16: =G16+X16+AI16 -> 0 | AN16: =AL16+AM16 -> 5000 | AR16: 500 | AS16: 500 | AT16: 500 | AU16: 500 | AV16: =AR16+AS16+AT16+AU16 -> 2000
B17: Activities Sub Total 1.3 | D17: =SUM(D13:D16) -> 9360 | E17: 3 | F17: =SUM(F13:F16) -> 24080 | G17: =SUM(G13:G16) -> 0 | H17: =SUM(H13:H16) -> 24080 | I17: 1 | K17: =SUM(K13:K16) -> 11120 | L17: =SUM(L13:L16) -> 0 | M17: =SUM(M13:M16) -> 11120 | O17: =SUM(O13:O16) -> 11120 | Q17: =SUM(Q13:Q16) -> 0 | R17: =SUM(R13:R16) -> 0 | S17: =O17+P17+Q17+R17 -> 11120 | U17: =SUM(U13:U16) -> 9360 | V17: 4 | W17: =SUM(W13:W16) -> 31440 | X17: =SUM(X13:X16) -> 0 | Y17: =SUM(Y13:Y16) -> 31440 | AB17: 4 | AC17: =SUM(AC13:AC16) -> 36480 | AD17: =SUM(AD13:AD16) -> 0 | AE17: =SUM(AE13:AE16) -> 36480 | AF17: =SUM(AF13:AF16) -> 9360 | AG17: 3 | AH17: =SUM(AH13:AH16) -> 24080 | AI17: =SUM(AI13:AI16) -> 0 | AJ17: =SUM(AJ13:AJ16) -> 24080 | AK17: =AG17+V17+E17 -> 10 | AL17: =SUM(AL13:AL16) -> 79600 | AM17: =SUM(AM13:AM16) -> 0 | AN17: =SUM(AN13:AN16) -> 79600 | AR17: =SUM(AR13:AR16) -> 10620 | AS17: =SUM(AS13:AS16) -> 8620 | AT17: =SUM(AT13:AT16) -> 8620 | AU17: =SUM(AU13:AU16) -> 8620 | AV17: =AR17+AS17+AT17+AU17 -> 36480
A18: 1.4 | B18: Training on Natural Resource Management a) Soil health ( Testing, treatment and preservation) b) Organic farming (Chemical free) c) Compost pit & its preparation d) Vermin compost making e) Bio- Pesticide f) Bio- fertilizer
A19: 1.4.1 | B19: Honorarium, travelling & food for resource person @Rs.2000 | C19: Resource person | D19: 2000 | E19: 2 | F19: =D19*E19 -> 4000 | H19: =F19+G19 -> 4000 | I19: 2 | J19: 2000 | K19: =I19*J19 -> 4000 | M19: =K19+L19 -> 4000 | O19: =J19 -> 2000 | R19: 2000 | S19: =O19+P19+Q19+R19 -> 4000 | U19: 2000 | V19: 4 | W19: =U19*V19 -> 8000 | Y19: =W19+X19 -> 8000 | AA19: 2000 | AB19: 4 | AC19: =AA19*AB19 -> 8000 | AE19: =AC19+AD19 -> 8000 | AF19: 2000 | AG19: 3 | AH19: =AF19*AG19 -> 6000 | AJ19: =AH19+AI19 -> 6000 | AK19: =E19+V19+AG19 -> 9 | AL19: =F19+W19+AH19 -> 18000 | AM19: =G19+X19+AI19 -> 0 | AN19: =AL19+AM19 -> 18000 | AR19: 2000 | AS19: 2000 | AT19: 2000 | AU19: 2000 | AV19: =AR19+AS19+AT19+AU19 -> 8000
A20: 1.4.2 | B20: Food for 35 participants form 7 project located villages each village 5 participants & 6 staff @ Rs.120 x 41 Person =Rs.3360 | C20: Fooding | D20: 3360 | E20: 2 | F20: =D20*E20 -> 6720 | H20: =F20+G20 -> 6720 | I20: 82 | J20: 120 | K20: =I20*J20 -> 9840 | M20: =K20+L20 -> 9840 | O20: =M20/2 -> 4920 | R20: =M20/2 -> 4920 | S20: =O20+P20+Q20+R20 -> 9840 | U20: 3360 | V20: 4 | W20: =U20*V20 -> 13440 | Y20: =W20+X20 -> 13440 | AA20: 4920 | AB20: 4 | AC20: =AA20*AB20 -> 19680 | AE20: =AC20+AD20 -> 19680 | AF20: 3360 | AG20: 3 | AH20: =AF20*AG20 -> 10080 | AJ20: =AH20+AI20 -> 10080 | AK20: =E20+V20+AG20 -> 9 | AL20: =F20+W20+AH20 -> 30240 | AM20: =G20+X20+AI20 -> 0 | AN20: =AL20+AM20 -> 30240 | AP20: Rectified the calculation | AR20: 4920 | AS20: 4920 | AT20: 4920 | AU20: 4920 | AV20: =AR20+AS20+AT20+AU20 -> 19680
A21: 1.4.3 | B21: Project village to training venue transportation charges Rs.7500/- each village 5 participants x 7 Project villges 3 vehicles for 2 trainings | C21: Travelling | D21: 3500 | E21: 2 | F21: =D21*E21 -> 7000 | H21: =F21+G21 -> 7000 | I21: =3*2 -> 6 | J21: 2500 | K21: =I21*J21 -> 15000 | M21: =K21+L21 -> 15000 | O21: =M21/2 -> 7500 | R21: =M21/2 -> 7500 | S21: =O21+P21+Q21+R21 -> 15000 | U21: 3500 | V21: 4 | W21: =U21*V21 -> 14000 | Y21: =W21+X21 -> 14000 | AA21: 2500 | AB21: 12 | AC21: =AA21*AB21 -> 30000 | AE21: =AC21+AD21 -> 30000 | AF21: 3500 | AG21: 3 | AH21: =AF21*AG21 -> 10500 | AJ21: =AH21+AI21 -> 10500 | AK21: =E21+V21+AG21 -> 9 | AL21: =F21+W21+AH21 -> 31500 | AM21: =G21+X21+AI21 -> 0 | AN21: =AL21+AM21 -> 31500 | AP21: We have calculated @Rs2500 as per budget description, 3 vehicles per training | AR21: 7500 | AS21: 7500 | AT21: 7500 | AU21: 7500 | AV21: =AR21+AS21+AT21+AU21 -> 30000
A22: 1.4.4 | B22: Arrangements & training matterials @ Rs.500/- | C22: matterials | D22: 500 | E22: 2 | F22: =D22*E22 -> 1000 | H22: =F22+G22 -> 1000 | I22: =2*35 -> 70 | J22: 50 | K22: =I22*J22 -> 3500 | M22: =K22+L22 -> 3500 | O22: =M22/2 -> 1750 | R22: =M22/2 -> 1750 | S22: =O22+P22+Q22+R22 -> 3500 | U22: 500 | V22: 4 | W22: =U22*V22 -> 2000 | Y22: =W22+X22 -> 2000 | AA22: 500 | AB22: 4 | AC22: =AA22*AB22 -> 2000 | AE22: =AC22+AD22 -> 2000 | AF22: 500 | AG22: 3 | AH22: =AF22*AG22 -> 1500 | AJ22: =AH22+AI22 -> 1500 | AK22: =E22+V22+AG22 -> 9 | AL22: =F22+W22+AH22 -> 4500 | AM22: =G22+X22+AI22 -> 0 | AN22: =AL22+AM22 -> 4500 | AR22: 500 | AS22: 500 | AT22: 500 | AU22: 500 | AV22: =AR22+AS22+AT22+AU22 -> 2000
B23: Activities Sub Total 1.4 | E23: 2 | F23: =SUM(F19:F22) -> 18720 | G23: =SUM(G19:G22) -> 0 | H23: =SUM(H19:H22) -> 18720 | I23: 2 | K23: =SUM(K19:K22) -> 32340 | L23: =SUM(L19:L22) -> 0 | M23: =SUM(M19:M22) -> 32340 | O23: =SUM(O19:O22) -> 16170 | P23: =SUM(P19:P22) -> 0 | Q23: =SUM(Q19:Q22) -> 0 | R23: =SUM(R19:R22) -> 16170 | S23: =O23+P23+Q23+R23 -> 32340 | V23: 4 | W23: =SUM(W19:W22) -> 37440 | X23: =SUM(X19:X22) -> 0 | Y23: =SUM(Y19:Y22) -> 37440 | AB23: 4 | AC23: =SUM(AC19:AC22) -> 59680 | AD23: =SUM(AD19:AD22) -> 0 | AE23: =SUM(AE19:AE22) -> 59680 | AG23: 3 | AH23: =SUM(AH19:AH22) -> 28080 | AI23: =SUM(AI19:AI22) -> 0 | AJ23: =SUM(AJ19:AJ22) -> 28080 | AK23: =AG23+V23+E23 -> 9 | AL23: =SUM(AL19:AL22) -> 84240 | AM23: =SUM(AM19:AM22) -> 0 | AN23: =SUM(AN19:AN22) -> 84240 | AO23: =SUM(AO19:AO22) -> 0 | AR23: =SUM(AR19:AR22) -> 14920 | AS23: =SUM(AS19:AS22) -> 14920 | AT23: =SUM(AT19:AT22) -> 14920 | AU23: =SUM(AU19:AU22) -> 14920 | AV23: =AR23+AS23+AT23+AU23 -> 59680
A24: 1.5 | B24: Pulses Seeds (Horse gram & Black gram) distribution
A25: 1.5.1 | B25: Pulses Seeds Distribution for 437 families Black Gram 2kg, Kulthi 2kg @Rs.360/- for 4 Kg x 437 families (Contribution Local labor charges@500 x 437 families) | C25: matterials | D25: 157320 | E25: 0 | F25: =D25*E25 -> 0 | G25: 0 | H25: =F25+G25 -> 0 | I25: 437 | J25: 212.86 | K25: =I25*J25 -> 93019.82 | M25: =K25+L25 -> 93019.82 | P25: =M25 -> 93019.82 | S25: =O25+P25+Q25+R25 -> 93019.82 | U25: 157320 | V25: 1 | W25: =U25*V25 -> 157320 | X25: 218500 | Y25: =W25+X25 -> 375820 | AA25: 157320 | AB25: 1 | AC25: =AA25*AB25 -> 157320 | AD25: 218500 | AE25: =AC25+AD25 -> 375820 | AF25: 157320 | AG25: 0 | AH25: =AF25*AG25 -> 0 | AJ25: =AH25+AI25 -> 0 | AK25: =E25+V25+AG25 -> 1 | AL25: =F25+W25+AH25 -> 157320 | AM25: =G25+X25+AI25 -> 218500 | AN25: =AL25+AM25 -> 375820 | AR25: 0 | AS25: 157320 | AT25: 0 | AU25: 0 | AV25: =AR25+AS25+AT25+AU25 -> 157320
B26: Activities Sub Total 1.5 | D26: =SUM(D25) -> 157320 | E26: =SUM(E25) -> 0 | F26: =SUM(F25) -> 0 | G26: =SUM(G25) -> 0 | H26: =SUM(H25) -> 0 | I26: 1 | K26: =SUM(K25) -> 93019.82 | L26: =SUM(L25) -> 0 | M26: =SUM(M25) -> 93019.82 | O26: =SUM(O25) -> 0 | P26: =SUM(P25) -> 93019.82 | Q26: =SUM(Q25) -> 0 | R26: =SUM(R25) -> 0 | S26: =O26+P26+Q26+R26 -> 93019.82 | U26: =SUM(U25) -> 157320 | V26: =SUM(V25) -> 1 | W26: =SUM(W25) -> 157320 | X26: =SUM(X25) -> 218500 | Y26: =SUM(Y25) -> 375820 | AB26: =SUM(AB25) -> 1 | AC26: =SUM(AC25) -> 157320 | AD26: =SUM(AD25) -> 218500 | AE26: =SUM(AE25) -> 375820 | AF26: =SUM(AF25) -> 157320 | AG26: =SUM(AG25) -> 0 | AH26: =SUM(AH25) -> 0 | AI26: =SUM(AI25) -> 0 | AJ26: =SUM(AJ25) -> 0 | AK26: =AG26+V26+E26 -> 1 | AL26: =SUM(AL25) -> 157320 | AM26: =SUM(AM25) -> 218500 | AN26: =SUM(AN25) -> 375820 | AO26: =SUM(AO25) -> 0 | AR26: =SUM(AR25) -> 0 | AS26: =SUM(AS25) -> 157320 | AT26: =SUM(AT25) -> 0 | AU26: =SUM(AU25) -> 0 | AV26: =AR26+AS26+AT26+AU26 -> 157320
A27: 1.6 | B27: Exposure visit on adaption of improved new technology
A28: 1.6.1 | B28: Honorarium for resource person @Rs.2000 | C28: Fooding | D28: 2000 | E28: 1 | F28: =D28*E28 -> 2000 | H28: =F28+G28 -> 2000 | K28: =I28*J28 -> 0 | M28: =K28+L28 -> 0 | S28: =O28+P28+Q28+R28 -> 0 | U28: 2000 | V28: 1 | W28: =U28*V28 -> 2000 | Y28: =W28+X28 -> 2000 | AF28: 2000 | AG28: 1 | AH28: =AF28*AG28 -> 2000 | AJ28: =AH28+AI28 -> 2000 | AK28: =E28+V28+AG28 -> 3 | AL28: =F28+W28+AH28 -> 6000 | AM28: =G28+X28+AI28 -> 0 | AN28: =AL28+AM28 -> 6000 | AO28: Why Honorarium is required for Exposure visit? | AP28: Exposure visit excluded due to shortage of fund. MUKUL: It has been included in additional budget in Year-1 | AV28: =AR28+AS28+AT28+AU28 -> 0
A29: 1.6.2 | B29: Food for 35 participants & 6 staff @ Rs.200 x 41 Person x 1 day = 8400/- | C29: Fooding | D29: 8400 | E29: 1 | F29: =D29*E29 -> 8400 | H29: =F29+G29 -> 8400 | K29: =I29*J29 -> 0 | M29: =K29+L29 -> 0 | S29: =O29+P29+Q29+R29 -> 0 | U29: 15400 | V29: 1 | W29: =U29*V29 -> 15400 | Y29: =W29+X29 -> 15400 | AF29: 16800 | AG29: 1 | AH29: =AF29*AG29 -> 16800 | AJ29: =AH29+AI29 -> 16800 | AK29: =E29+V29+AG29 -> 3 | AL29: =F29+W29+AH29 -> 40600 | AM29: =G29+X29+AI29 -> 0 | AN29: =AL29+AM29 -> 40600 | AV29: =AR29+AS29+AT29+AU29 -> 0
A30: 1.6.3 | B30: Bus charges @ Rs.25000/- in Year -1 @ Rs. 26000/- x 2 bus in Year-2 and for Long distance place Exposure Visit in Yr-3 Bus Charges @Rs.35000/- | C30: Travelling | D30: 25000 | E30: 1 | F30: =D30*E30 -> 25000 | H30: =F30+G30 -> 25000 | K30: =I30*J30 -> 0 | M30: =K30+L30 -> 0 | S30: =O30+P30+Q30+R30 -> 0 | U30: 52000 | V30: 1 | W30: =U30*V30 -> 52000 | Y30: =W30+X30 -> 52000 | AF30: 35000 | AG30: 1 | AH30: =AF30*AG30 -> 35000 | AJ30: =AH30+AI30 -> 35000 | AK30: =E30+V30+AG30 -> 3 | AL30: =F30+W30+AH30 -> 112000 | AM30: =G30+X30+AI30 -> 0 | AN30: =AL30+AM30 -> 112000 | AV30: =AR30+AS30+AT30+AU30 -> 0
A31: 1.6.4 | B31: First Aid medicine & other expenses @ Rs.500/- and Rs.1000/- | C31: matterials | D31: 500 | E31: 1 | F31: =D31*E31 -> 500 | H31: =F31+G31 -> 500 | K31: =I31*J31 -> 0 | M31: =K31+L31 -> 0 | S31: =O31+P31+Q31+R31 -> 0 | U31: 1000 | V31: 1 | W31: =U31*V31 -> 1000 | Y31: =W31+X31 -> 1000 | AF31: 1000 | AG31: 1 | AH31: =AF31*AG31 -> 1000 | AJ31: =AH31+AI31 -> 1000 | AK31: =E31+V31+AG31 -> 3 | AL31: =F31+W31+AH31 -> 2500 | AM31: =G31+X31+AI31 -> 0 | AN31: =AL31+AM31 -> 2500 | AV31: =AR31+AS31+AT31+AU31 -> 0
B32: Activities Sub Total 1.6 | D32: =SUM(D28:D31) -> 35900 | E32: 1 | F32: =SUM(F28:F31) -> 35900 | G32: =SUM(G28:G31) -> 0 | H32: =SUM(H28:H31) -> 35900 | I32: 0 | K32: =SUM(K28:K31) -> 0 | L32: =SUM(L28:L31) -> 0 | M32: =SUM(M28:M31) -> 0 | O32: =SUM(O28:O31) -> 0 | P32: =SUM(P28:P31) -> 0 | Q32: =SUM(Q28:Q31) -> 0 | R32: =SUM(R28:R31) -> 0 | S32: =O32+P32+Q32+R32 -> 0 | U32: =SUM(U28:U31) -> 70400 | V32: 1 | W32: =SUM(W28:W31) -> 70400 | X32: =SUM(X28:X31) -> 0 | Y32: =SUM(Y28:Y31) -> 70400 | AA32: =SUM(AA28:AA31) -> 0 | AB32: =SUM(AB28:AB31) -> 0 | AC32: =SUM(AC28:AC31) -> 0 | AD32: =SUM(AD28:AD31) -> 0 | AE32: =SUM(AE28:AE31) -> 0 | AF32: =SUM(AF28:AF31) -> 54800 | AG32: 1 | AH32: =SUM(AH28:AH31) -> 54800 | AI32: =SUM(AI28:AI31) -> 0 | AJ32: =SUM(AJ28:AJ31) -> 54800 | AK32: =AG32+V32+E32 -> 3 | AL32: =SUM(AL28:AL31) -> 161100 | AM32: =SUM(AM28:AM31) -> 0 | AN32: =SUM(AN28:AN31) -> 161100 | AO32: =SUM(AO28:AO31) -> 0 | AR32: =SUM(AR28:AR31) -> 0 | AS32: =SUM(AS28:AS31) -> 0 | AT32: =SUM(AT28:AT31) -> 0 | AU32: =SUM(AU28:AU31) -> 0 | AV32: =AR32+AS32+AT32+AU32 -> 0
B33: Activities Sub Total for Outcomes :1 | D33: =SUM(D11+D17+D23+D26+D32) -> 209240 | E33: =SUM(E11+E17+E23+E26+E32) -> 18 | F33: =SUM(F11+F17+F23+F26+F32) -> 158620 | G33: =SUM(G11+G17+G23+G26+G32) -> 0 | H33: =SUM(H11+H17+H23+H26+H32) -> 158620 | K33: =SUM(K11+K17+K23+K26+K32) -> 232929.82 | L33: =SUM(L11+L17+L23+L26+L32) -> 0 | M33: =SUM(M11+M17+M23+M26+M32) -> 232929.82 | O33: =SUM(O11+O17+O23+O26+O32) -> 63935 | P33: =SUM(P11+P17+P23+P26+P32) -> 112954.82 | Q33: =SUM(Q11+Q17+Q23+Q26+Q32) -> 19935 | R33: =SUM(R11+R17+R23+R26+R32) -> 36105 | S33: =SUM(S11+S17+S23+S26+S32) -> 232929.82 | U33: =SUM(U11+U17+U23+U26+U32) -> 243740 | V33: =SUM(V11+V17+V23+V26+V32) -> 22 | W33: =SUM(W11+W17+W23+W26+W32) -> 376520 | X33: =SUM(X11+X17+X23+X26+X32) -> 218500 | Y33: =SUM(Y11+Y17+Y23+Y26+Y32) -> 595020 | AC33: =SUM(AC11+AC17+AC23+AC26+AC32) -> 333400 | AD33: =SUM(AD11+AD17+AD23+AD26+AD32) -> 218500 | AE33: =SUM(AE11+AE17+AE23+AE26+AE32) -> 551900 | AF33: =SUM(AF11+AF17+AF23+AF26+AF32) -> 228140 | AG33: =SUM(AG11+AG17+AG23+AG26+AG32) -> 19 | AH33: =SUM(AH11+AH17+AH23+AH26+AH32) -> 186880 | AI33: =SUM(AI11+AI17+AI23+AI26+AI32) -> 0 | AJ33: =SUM(AJ11+AJ17+AJ23+AJ26+AJ32) -> 186880 | AL33: =SUM(AL11+AL17+AL23+AL26+AL32) -> 722020 | AM33: =SUM(AM11+AM17+AM23+AM26+AM32) -> 218500 | AN33: =SUM(AN11+AN17+AN23+AN26+AN32) -> 940520 | AO33: =SUM(AO11+AQ17+AO23+AO26+AO32) -> 0 | AP33: =AC33+AD33 -> 551900 | AQ33: =SUM(AQ11+AQ17+AQ23+AQ26+AQ32) -> 0 | AR33: =SUM(AR11+AR17+AR23+AR26+AR32) -> 45520 | AS33: =SUM(AS11+AS17+AS23+AS26+AS32) -> 200840 | AT33: =SUM(AT11+AT17+AT23+AT26+AT32) -> 43520 | AU33: =SUM(AU11+AU17+AU23+AU26+AU32) -> 43520 | AV33: =AR33+AS33+AT33+AU33 -> 333400
B34: Activities for Outcome :2
A35: 2.1 | B35: Training to the CBO’s (SHG) on topics a) Account book keeping, b) Record maintaining, c) Rules and Regulations, d) Responsibilities of the group leaders and members. e) Training on loan taking and refunding. f) Sack bag potatoes farming g) tuber crop farming i) Encourage to farming of Millet ( Mandia)
A36: 2.1.1 | B36: Honorarium , Travelling & food for Resource person @Rs.2000 | C36: Resource person | D36: 2000 | E36: 2 | F36: =D36*E36 -> 4000 | H36: =F36+G36 -> 4000 | I36: 2 | J36: 2000 | K36: =I36*J36 -> 4000 | M36: =K36+L36 -> 4000 | Q36: =M36/2 -> 2000 | R36: 2000 | S36: =O36+P36+Q36+R36 -> 4000 | U36: 2000 | V36: 4 | W36: =U36*V36 -> 8000 | Y36: =W36+X36 -> 8000 | AA36: 2000 | AB36: 4 | AC36: =AA36*AB36 -> 8000 | AE36: =AC36+AD36 -> 8000 | AF36: 2000 | AG36: 3 | AH36: =AF36*AG36 -> 6000 | AJ36: =AH36+AI36 -> 6000 | AK36: =E36+V36+AG36 -> 9 | AL36: =F36+W36+AH36 -> 18000 | AM36: =G36+X36+AI36 -> 0 | AN36: =AL36+AM36 -> 18000 | AR36: 2000 | AS36: 2000 | AT36: 2000 | AU36: 2000 | AV36: =AR36+AS36+AT36+AU36 -> 8000
A37: 2.1.2 | B37: Food for 35 participants form 7 project located villages each village 5 participants & 6 staff @ Rs.120 x 42 Person =Rs.3360 | C37: Fooding | D37: 3360 | E37: 2 | F37: =D37*E37 -> 6720 | H37: =F37+G37 -> 6720 | I37: =2*41 -> 82 | J37: 120 | K37: =I37*J37 -> 9840 | M37: =K37+L37 -> 9840 | Q37: =M37/2 -> 4920 | R37: 4920 | S37: =O37+P37+Q37+R37 -> 9840 | U37: 3360 | V37: 4 | W37: =U37*V37 -> 13440 | Y37: =W37+X37 -> 13440 | AA37: 4920 | AB37: 4 | AC37: =AA37*AB37 -> 19680 | AE37: =AC37+AD37 -> 19680 | AF37: 3360 | AG37: 3 | AH37: =AF37*AG37 -> 10080 | AJ37: =AH37+AI37 -> 10080 | AK37: =E37+V37+AG37 -> 9 | AL37: =F37+W37+AH37 -> 30240 | AM37: =G37+X37+AI37 -> 0 | AN37: =AL37+AM37 -> 30240 | AP37: Rectified the calculation | AR37: 4920 | AS37: 4920 | AT37: 4920 | AU37: 4920 | AV37: =AR37+AS37+AT37+AU37 -> 19680
A38: 2.1.3 | B38: Project village to training venue transportation charges Rs.2500/- each village 5 participants x 7 Project villages, 2 vehicles | C38: Travelling | D38: 3500 | E38: 2 | F38: =D38*E38 -> 7000 | H38: =F38+G38 -> 7000 | I38: 2 | J38: =2*2500 -> 5000 | K38: =I38*J38 -> 10000 | M38: =K38+L38 -> 10000 | Q38: =M38/2 -> 5000 | R38: 5000 | S38: =O38+P38+Q38+R38 -> 10000 | U38: 3500 | V38: 4 | W38: =U38*V38 -> 14000 | Y38: =W38+X38 -> 14000 | AA38: 2500 | AB38: 8 | AC38: =AA38*AB38 -> 20000 | AE38: =AC38+AD38 -> 20000 | AF38: 3500 | AG38: 3 | AH38: =AF38*AG38 -> 10500 | AJ38: =AH38+AI38 -> 10500 | AK38: =E38+V38+AG38 -> 9 | AL38: =F38+W38+AH38 -> 31500 | AM38: =G38+X38+AI38 -> 0 | AN38: =AL38+AM38 -> 31500 | AP38: We have calculated @Rs2500 as per budget description 2 vehicles per training. | AQ38: =2500*4*4 -> 40000 | AR38: 5000 | AS38: 5000 | AT38: 5000 | AU38: 5000 | AV38: =AR38+AS38+AT38+AU38 -> 20000
A39: 2.1.4 | B39: Arrangements & training materials @ Rs.500/- | C39: matterials | D39: 500 | E39: 2 | F39: =D39*E39 -> 1000 | H39: =F39+G39 -> 1000 | I39: 70 | J39: 50 | K39: =I39*J39 -> 3500 | M39: =K39+L39 -> 3500 | Q39: =M39/2 -> 1750 | R39: 1750 | S39: =O39+P39+Q39+R39 -> 3500 | U39: 500 | V39: 4 | W39: =U39*V39 -> 2000 | Y39: =W39+X39 -> 2000 | AA39: 500 | AB39: 4 | AC39: =AA39*AB39 -> 2000 | AE39: =AC39+AD39 -> 2000 | AF39: 500 | AG39: 3 | AH39: =AF39*AG39 -> 1500 | AJ39: =AH39+AI39 -> 1500 | AK39: =E39+V39+AG39 -> 9 | AL39: =F39+W39+AH39 -> 4500 | AM39: =G39+X39+AI39 -> 0 | AN39: =AL39+AM39 -> 4500 | AR39: 500 | AS39: 500 | AT39: 500 | AU39: 500 | AV39: =AR39+AS39+AT39+AU39 -> 2000
B40: Activities Sub Total 2.1 | D40: =SUM(D36:D39) -> 9360 | E40: 2 | F40: =SUM(F36:F39) -> 18720 | G40: =SUM(G36:G39) -> 0 | H40: =SUM(H36:H39) -> 18720 | I40: 2 | K40: =SUM(K36:K39) -> 27340 | L40: =SUM(L36:L39) -> 0 | M40: =SUM(M36:M39) -> 27340 | O40: =SUM(O36:O39) -> 0 | P40: =SUM(P36:P39) -> 0 | Q40: =SUM(Q36:Q39) -> 13670 | R40: =SUM(R36:R39) -> 13670 | S40: =O40+P40+Q40+R40 -> 27340 | U40: =SUM(U36:U39) -> 9360 | V40: 4 | W40: =SUM(W36:W39) -> 37440 | X40: =SUM(X36:X39) -> 0 | Y40: =SUM(Y36:Y39) -> 37440 | AB40: 4 | AC40: =SUM(AC36:AC39) -> 49680 | AD40: =SUM(AD36:AD39) -> 0 | AE40: =SUM(AE36:AE39) -> 49680 | AF40: =SUM(AF36:AF39) -> 9360 | AG40: 3 | AH40: =SUM(AH36:AH39) -> 28080 | AI40: =SUM(AI36:AI39) -> 0 | AJ40: =SUM(AJ36:AJ39) -> 28080 | AK40: =AG40+V40+E40 -> 9 | AL40: =SUM(AL36:AL39) -> 84240 | AM40: =SUM(AM36:AM39) -> 0 | AN40: =SUM(AN36:AN39) -> 84240 | AO40: =SUM(AO36:AO39) -> 0 | AR40: =SUM(AR36:AR39) -> 12420 | AS40: =SUM(AS36:AS39) -> 12420 | AT40: =SUM(AT36:AT39) -> 12420 | AU40: =SUM(AU36:AU39) -> 12420 | AV40: =AR40+AS40+AT40+AU40 -> 49680
...

Sheet Summary Sheet
A1: Project Title: Ensuring food and livelihood security of indigenous and other marginalized communities in Thakurmunda Block, Mayurbhanj, Odisha
A2: Accounting Period From 01. April-2024 to 31.March 2025
A3: Project Partner: DAPTA (Development Agency for Poor and Tribal Awakening)
A4: Contact person | C4: Aadarsh Bharat Mishra Sharma ( +91 94370 29124)
A5: E-mail ID | C5: dapta@rediffmail.com
A6: Summery sheet of Project Grant & Expenses in Year-2- 2024-25
A7: Total Approved Budget in 2024-25 | C7: 2917500 | K7: TOTAL
A8: MCC Share in budget for 2024-25 | C8: 2675000
A9: Cash in hand from 2024-25 | C9: 0
A10: Balance in bank (minimum bal to be maintained,not to be used for project) | C10: 0 | K10: =C8+C9 -> 2675000
D11: 1st Qtr | F11: 2nd Qtr | H11: 3rd Qtr. | J11: 4th Qtr.
A12: Total Brought Forward | C12: → | D12: 67601.6 | F12: =D22 -> 111252.22 | H12: =F22 -> 70766.32 | J12: =H22 -> 21424.2 | K12: =C9 -> 0
A14: MCC Grant Received | C14: → | D14: 577475 | F14: 720885 | H14: 526803 | K14: =SUM(D14+F14+H14+J14) -> 1825163
K15: =SUM(D15+F15+H15+J15) -> 0
A16: Bank Interest earned | C16: → | D16: 2150 | F16: 2994 | H16: 2912 | K16: =SUM(D16+F16+H16+J16) -> 8056
K17: =SUM(D17+F17+H17+J17) -> 0
A18: Total Available | C18: → | D18: =SUM(D12+D14+D16) -> 647226.6 | F18: =SUM(F12+F14+F16) -> 835131.22 | H18: =SUM(H12+H14+H16) -> 600481.32 | K18: =D12+K14+K16 -> 1900820.6
K19: =SUM(D19+F19+H19+J19) -> 0
A20: Grant utilization | C20: → | D20: 535974.38 | F20: 764364.9 | H20: 579057.12 | K20: =SUM(D20+F20+H20+J20) -> 1879396.4
A22: Balance available | C22: → | D22: =D18-D20 -> 111252.22 | F22: =F18-F20 -> 70766.32 | H22: =H18-H20 -> 21424.2 | J22: =J18-J20 -> 0 | K22: =K18-K20 -> 21424.2

Sheet Budget Comparison
B1: Partner: DAPTA (Development Agency for Poor and Tribal Awakening)
A2: Project Title: Ensuring food and livelihood security of indigenous and other marginalized communities in Thakurmunda Block, Mayurbhanj, Odisha
A3: Accounting Period From 01. April 2024 to 31.March 2025
A4: ID | B4: Description | C4: Year-2 | D4: 1st Qtr Exp. | E4: 2nd Qtr Exp. | F4: 3rd Qtr Exp. | G4: 4th Qtr Exp. | H4: TOTAL Expenses | I4: EXPENSES % | J4: UNSPENT BUDGET balance | K4: UNSPENT % | L4: Explanation for significant variance (< or >10%)
C5: Approved MCC Budget
A6: 1 | B6: Outcome :1 Activities
A7: 1.1 | B7: Baseline | C7: 0 | D7: =+' Qtr-1 April-24 to June-24 '!F17 -> 0 | E7: =+' Qtr- 2 July-24 to Sept-24 (2)'!F17 -> 0 | F7: =+' Qtr-3 Octo-24 to Dec-24'!F18 -> 0 | G7: =+' Qtr-4 Jan-25 to march-25'!F16 -> 0 | H7: =SUM(D7:G7) -> 0 | I7: =H7/C7 -> #DIV/0! | J7: =C7-H7 -> 0 | K7: =J7/C7 -> #DIV/0!
A8: 1.2 | B8: Monthly PRA/ Data collection/ Village Community Meeting
A9: 1.2.1 | B9: Monthly Village Community Meeting (Biscuits / Snacks /per time /12 Months) @Rs.15 x 437 + 6 staff =Rs.6660/- | C9: 79920 | D9: =+' Qtr-1 April-24 to June-24 '!F23 -> 19365 | E9: =+' Qtr- 2 July-24 to Sept-24 (2)'!F23 -> 17580 | F9: =+' Qtr-3 Octo-24 to Dec-24'!F24 -> 18735 | G9: =+' Qtr-4 Jan-25 to march-25'!F21 -> 0 | H9: =SUM(D9:G9) -> 55680 | I9: =H9/C9 -> 0.6966967 | J9: =C9-H9 -> 24240 | K9: =J9/C9 -> 0.3033033
B10: Activities Sub Total 1.2 | C10: =SUM(C7,C9) -> 79920 | D10: =SUM(D7,D9) -> 19365 | E10: =SUM(E7,E9) -> 17580 | F10: =SUM(F7,F9) -> 18735 | G10: =SUM(G7,G9) -> 0 | H10: =SUM(H7,H9) -> 55680 | J10: =SUM(J7,J9) -> 24240 | K10: =J10/C10 -> 0.3033033
A11: 1.3 | B11: Training on Improved agriculture methods and Technology :- a) SRI (Paddy farming in row) b) Multi cropping c) Crop diversification d) Crop rotation e) Azola growing f) Seed preservation g) Seed treatment
A12: 1.3.1 | B12: Honorarium , travelling & food for resource person @Rs.2000 (above mentioned some subject will be conducted by the Project staff) | C12: 2000 | D12: =+' Qtr-1 April-24 to June-24 '!F30 -> 1960 | E12: =+' Qtr- 2 July-24 to Sept-24 (2)'!F28 -> 0 | F12: =+' Qtr-3 Octo-24 to Dec-24'!F31 -> 0 | G12: =+' Qtr-4 Jan-25 to march-25'!F28 -> 0 | H12: =SUM(D12:G12) -> 1960 | I12: =H12/C12 -> 0.98 | J12: =C12-H12 -> 40 | K12: =J12/C12 -> 0.02
A13: 1.3.2 | B13: Food for 20 participants & 6 staff @ Rs.120 x 26 Person | C13: 12480 | D13: =+' Qtr-1 April-24 to June-24 '!F35 -> 3120 | E13: =+' Qtr- 2 July-24 to Sept-24 (2)'!F31 -> 0 | F13: =+' Qtr-3 Octo-24 to Dec-24'!F36 -> 6120 | G13: =+' Qtr-4 Jan-25 to march-25'!F33 -> 0 | H13: =SUM(D13:G13) -> 9240 | I13: =H13/C13 -> 0.74038462 | J13: =C13-H13 -> 3240 | K13: =J13/C13 -> 0.25961538
A14: 1.3.3 | B14: Project village to training venue Transportation charges 20 participants x 1 Project villages @ Rs.2500/-; 2 vehicles | C14: 20000 | D14: =+' Qtr-1 April-24 to June-24 '!F39 -> 5000 | E14: =+' Qtr- 2 July-24 to Sept-24 (2)'!F34 -> 0 | F14: =+' Qtr-3 Octo-24 to Dec-24'!F41 -> 10000 | G14: =+' Qtr-4 Jan-25 to march-25'!F37 -> 0 | H14: =SUM(D14:G14) -> 15000 | I14: =H14/C14 -> 0.75 | J14: =C14-H14 -> 5000 | K14: =J14/C14 -> 0.25
A15: 1.3.4 | B15: Arrangements & training matterials @ Rs.500/- | C15: 2000 | D15: =+' Qtr-1 April-24 to June-24 '!F43 -> 500 | E15: =+' Qtr- 2 July-24 to Sept-24 (2)'!F37 -> 0 | F15: =+' Qtr-3 Octo-24 to Dec-24'!F45 -> 900 | G15: =+' Qtr-4 Jan-25 to march-25'!F41 -> 0 | H15: =SUM(D15:G15) -> 1400 | I15: =H15/C15 -> 0.7 | J15: =C15-H15 -> 600 | K15: =J15/C15 -> 0.3
B16: Activities Sub Total 1.3 | C16: =SUM(C12:C15) -> 36480 | D16: =SUM(D12:D15) -> 10580 | E16: =SUM(E12:E15) -> 0 | F16: =SUM(F12:F15) -> 17020 | G16: =SUM(G12:G15) -> 0 | H16: =SUM(H12:H15) -> 27600 | I16: =SUM(I12:I15) -> 3.1703846 | J16: =SUM(J12:J15) -> 8880 | K16: =J16/C16 -> 0.24342105 | L16: =SUM(L12:L15) -> 0
A17: 1.4 | B17: Training on Natural Resource Management a) Soil health ( Testing, treatment and preservation) b) Organic farming (Chemical free) c) Compost pit & its preparation d) Vermin compost making e) Bio- Pesticide f) Bio- fertilizer
A18: 1.4.1 | B18: Honorarium, travelling & food for resource person @Rs.2000 | C18: 8000 | D18: =+' Qtr-1 April-24 to June-24 '!F49 -> 1990 | E18: =+' Qtr- 2 July-24 to Sept-24 (2)'!F43 -> 1930 | F18: =+' Qtr-3 Octo-24 to Dec-24'!F51 -> 4000 | G18: =+' Qtr-4 Jan-25 to march-25'!F46 -> 0 | H18: =SUM(D18:G18) -> 7920 | I18: =H18/C18 -> 0.99 | J18: =C18-H18 -> 80 | K18: =J18/C18 -> 0.01
A19: 1.4.2 | B19: Food for 35 participants form 7 project located villages each village 5 participants & 6 staff @ Rs.120 x 41 Person =Rs.3360 | C19: 19680 | D19: =+' Qtr-1 April-24 to June-24 '!F53 -> 4920 | E19: =+' Qtr- 2 July-24 to Sept-24 (2)'!F47 -> 4680 | F19: =+' Qtr-3 Octo-24 to Dec-24'!F55 -> 9360 | G19: =+' Qtr-4 Jan-25 to march-25'!F50 -> 0 | H19: =SUM(D19:G19) -> 18960 | I19: =H19/C19 -> 0.96341463 | J19: =C19-H19 -> 720 | K19: =J19/C19 -> 0.036585366
A20: 1.4.3 | B20: Project village to training venue transportation charges Rs.7500/- each village 5 participants x 7 Project villges 3 vehicles for 2 trainings | C20: 30000 | D20: =+' Qtr-1 April-24 to June-24 '!F57 -> 5000 | E20: =+' Qtr- 2 July-24 to Sept-24 (2)'!F51 -> 5000 | F20: =+' Qtr-3 Octo-24 to Dec-24'!F59 -> 10000 | G20: =+' Qtr-4 Jan-25 to march-25'!F54 -> 0 | H20: =SUM(D20:G20) -> 20000 | I20: =H20/C20 -> 0.66666667 | J20: =C20-H20 -> 10000 | K20: =J20/C20 -> 0.33333333
A21: 1.4.4 | B21: Arrangements & training matterials @ Rs.500/- | C21: 2000 | D21: =+' Qtr-1 April-24 to June-24 '!F61 -> 525 | E21: =+' Qtr- 2 July-24 to Sept-24 (2)'!F55 -> 525 | F21: =+' Qtr-3 Octo-24 to Dec-24'!F63 -> 990 | G21: =+' Qtr-4 Jan-25 to march-25'!F58 -> 0 | H21: =SUM(D21:G21) -> 2040 | I21: =H21/C21 -> 1.02 | J21: =C21-H21 -> -40 | K21: =J21/C21 -> -0.02
B22: Activities Sub Total 1.4 | C22: =SUM(C18:C21) -> 59680 | D22: =SUM(D18:D21) -> 12435 | E22: =SUM(E18:E21) -> 12135 | F22: =SUM(F18:F21) -> 24350 | G22: =SUM(G18:G21) -> 0 | H22: =SUM(H18:H21) -> 48920 | I22: =SUM(I18:I21) -> 3.6400813 | J22: =SUM(J18:J21) -> 10760 | K22: =J22/C22 -> 0.18029491 | L22: =SUM(L18:L21) -> 0
A23: 1.5 | B23: Pulses Seeds (Horse gram & Black gram) distribution
A24: 1.5.1 | B24: Pulses Seeds Distribution for 437 families Black Gram 1kg, Kulthi 1kg @Rs.212.86/- for 2 Kg x 437 families (Contribution Local labor charges@500 x 437 families) | C24: 157320 | D24: =+' Qtr-1 April-24 to June-24 '!F66 -> 0 | E24: =+' Qtr- 2 July-24 to Sept-24 (2)'!F60 -> 154754 | F24: =+' Qtr-3 Octo-24 to Dec-24'!F68 -> 3500 | G24: =+' Qtr-4 Jan-25 to march-25'!F63 -> 0 | H24: =SUM(D24:G24) -> 158254 | I24: =H24/C24 -> 1.0059369 | J24: =C24-H24 -> -934 | K24: =J24/C24 -> -0.0059369438
B25: Activities Sub Total 1.5 | C25: =C24 -> 157320 | D25: =D24 -> 0 | E25: =E24 -> 154754 | F25: =F24 -> 3500 | G25: =G24 -> 0 | H25: =H24 -> 158254 | I25: =I24 -> 1.0059369 | J25: =J24 -> -934 | K25: =J25/C25 -> -0.0059369438 | L25: =L24 -> 0
A26: 1.6 | B26: Exposure visit on adaption of improved new technology
A27: 1.6.1 | B27: Honorarium for resource person @Rs.2000 | C27: 0 | D27: =+' Qtr-1 April-24 to June-24 '!F69 -> 0 | E27: =+' Qtr- 2 July-24 to Sept-24 (2)'!F65 -> 0 | F27: =+' Qtr-3 Octo-24 to Dec-24'!F73 -> 0 | G27: =+' Qtr-4 Jan-25 to march-25'!F68 -> 0 | H27: =SUM(D27:G27) -> 0 | I27: =H27/C27 -> #DIV/0! | J27: =C27-H27 -> 0 | K27: =J27/C27 -> #DIV/0!
A28: 1.6.2 | B28: Food for 35 participants & 6 staff @ Rs.200 x 41 Person x 1 day = 8400/- | C28: 0 | D28: =+' Qtr-1 April-24 to June-24 '!F70 -> 0 | E28: =+' Qtr- 2 July-24 to Sept-24 (2)'!F68 -> 0 | F28: =+' Qtr-3 Octo-24 to Dec-24'!F76 -> 0 | G28: =+' Qtr-4 Jan-25 to march-25'!F71 -> 0 | H28: =SUM(D28:G28) -> 0 | I28: =H28/C28 -> #DIV/0! | J28: =C28-H28 -> 0 | K28: =J28/C28 -> #DIV/0!
A29: 1.6.3 | B29: Bus charges @ Rs.25000/- in Year -1 @ Rs. 26000/- x 2 bus in Year-2 and for Long distance place Exposure Visit in Yr-3 Bus Charges @Rs.35000/- | C29: 0 | D29: =+' Qtr-1 April-24 to June-24 '!F71 -> 0 | E29: =+' Qtr- 2 July-24 to Sept-24 (2)'!F71 -> 0 | F29: =+' Qtr-3 Octo-24 to Dec-24'!F79 -> 0 | G29: =+' Qtr-4 Jan-25 to march-25'!F75 -> 0 | H29: =SUM(D29:G29) -> 0 | I29: =H29/C29 -> #DIV/0! | J29: =C29-H29 -> 0 | K29: =J29/C29 -> #DIV/0!
A30: 1.6.4 | B30: First Aid medicine & other expenses @ Rs.500/- and Rs.1000/- | C30: 0 | D30: =+' Qtr-1 April-24 to June-24 '!F72 -> 0 | E30: =+' Qtr- 2 July-24 to Sept-24 (2)'!F74 -> 0 | F30: =+' Qtr-3 Octo-24 to Dec-24'!F82 -> 0 | G30: =+' Qtr-4 Jan-25 to march-25'!F79 -> 0 | H30: =SUM(D30:G30) -> 0 | I30: =H30/C30 -> #DIV/0! | J30: =C30-H30 -> 0 | K30: =J30/C30 -> #DIV/0!
B31: Activities Sub Total 1.6 | C31: =SUM(C27:C30) -> 0 | D31: =SUM(D27:D30) -> 0 | E31: =SUM(E27:E30) -> 0 | F31: =SUM(F27:F30) -> 0 | G31: =SUM(G27:G30) -> 0 | H31: =SUM(H27:H30) -> 0 | I31: =SUM(I27:I30) -> #DIV/0! | J31: =SUM(J27:J30) -> 0 | K31: =J31/C31 -> #DIV/0! | L31: =SUM(L27:L30) -> 0
B32: Activities Sub Total for Outcomes :1 | C32: =SUM(C31,C25,C22,C16,C10) -> 333400 | D32: =SUM(D31,D25,D22,D16,D10) -> 42380 | E32: =SUM(E31,E25,E22,E16,E10) -> 184469 | F32: =SUM(F31,F25,F22,F16,F10) -> 63605 | G32: =SUM(G31,G25,G22,G16,G10) -> 0 | H32: =SUM(H31,H25,H22,H16,H10) -> 290454 | I32: =SUM(I31,I25,I22,I16,I10) -> #DIV/0! | J32: =SUM(J31,J25,J22,J16,J10) -> 42946 | K32: =J32/C32 -> 0.12881224 | L32: =SUM(L31,L25,L22,L16,L10) -> 0
B33: Activities for Outcome :2
A34: 2.1 | B34: Training to the CBO’s (SHG) on topics a) Account book keeping, b) Record maintaining, c) Rules and Regulations, d) Responsibilities of the group leaders and members. e) Training on loan taking and refunding. f) Sack bag potatoes farming g) tuber crop farming i) Encourage to farming of Millet ( Mandia)
A35: 2.1.1 | B35: Honorarium , Travelling & food for Resource person @Rs.2000 | C35: 8000 | D35: =+' Qtr-1 April-24 to June-24 '!F80 -> 1990 | E35: =+' Qtr- 2 July-24 to Sept-24 (2)'!F82 -> 1930 | F35: =+' Qtr-3 Octo-24 to Dec-24'!F90 -> 1930 | G35: =+' Qtr-4 Jan-25 to march-25'!F87 -> 0 | H35: =SUM(D35:G35) -> 5850 | I35: =H35/C35 -> 0.73125 | J35: =C35-H35 -> 2150 | K35: =J35/C35 -> 0.26875
A36: 2.1.2 | B36: Food for 35 participants form 7 project located villages each village 5 participants & 6 staff @ Rs.120 x 42 Person =Rs.3360 | C36: 19680 | D36: =+' Qtr-1 April-24 to June-24 '!F84 -> 4920 | E36: =+' Qtr- 2 July-24 to Sept-24 (2)'!F86 -> 4440 | F36: =+' Qtr-3 Octo-24 to Dec-24'!F94 -> 4680 | G36: =+' Qtr-4 Jan-25 to march-25'!F91 -> 0 | H36: =SUM(D36:G36) -> 14040 | I36: =H36/C36 -> 0.71341463 | J36: =C36-H36 -> 5640 | K36: =J36/C36 -> 0.28658537
A37: 2.1.3 | B37: Project village to training venue transportation charges Rs.2500/- each village 5 participants x 7 Project villages, 2 vehicles | C37: 20000 | D37: =+' Qtr-1 April-24 to June-24 '!F88 -> 5000 | E37: =+' Qtr- 2 July-24 to Sept-24 (2)'!F90 -> 5000 | F37: =+' Qtr-3 Octo-24 to Dec-24'!F98 -> 5000 | G37: =+' Qtr-4 Jan-25 to march-25'!F95 -> 0 | H37: =SUM(D37:G37) -> 15000 | I37: =H37/C37 -> 0.75 | J37: =C37-H37 -> 5000 | K37: =J37/C37 -> 0.25
A38: 2.1.4 | B38: Arrangements & training materials @ Rs.500/- | C38: 2000 | D38: =+' Qtr-1 April-24 to June-24 '!F92 -> 525 | E38: =+' Qtr- 2 July-24 to Sept-24 (2)'!F94 -> 465 | F38: =+' Qtr-3 Octo-24 to Dec-24'!F102 -> 495 | G38: =+' Qtr-4 Jan-25 to march-25'!F99 -> 0 | H38: =SUM(D38:G38) -> 1485 | I38: =H38/C38 -> 0.7425 | J38: =C38-H38 -> 515 | K38: =J38/C38 -> 0.2575
B39: Activities Sub Total 2.1 | C39: =SUM(C35:C38) -> 49680 | D39: =SUM(D35:D38) -> 12435 | E39: =SUM(E35:E38) -> 11835 | F39: =SUM(F35:F38) -> 12105 | G39: =SUM(G35:G38) -> 0 | H39: =SUM(H35:H38) -> 36375 | I39: =SUM(I35:I38) -> 2.9371646 | J39: =SUM(J35:J38) -> 13305 | K39: =J39/C39 -> 0.26781401 | L39: =SUM(L35:L38) -> 0
A40: 2.2 | B40: Trainings on Alternate Livelihood Options: Poultry & Goat Rearing
...

Sheet  Qtr-1 April-24 to June-24 
B1: Partner: DAPTA (Development Agency for Poor and Tribal Awakening)
A2: Quarterly/Monthly Reporting Format
A3: Ensuring food and livelihood security of indigenous and other marginalized communities in Thakurmunda Block, Mayurbhanj, Odisha
D4: Accounting Period: | E4: Start: 1 April 2024
E5: End: 30 June 2024
A6: Date: Grant received on | D6: 02.05.2024 | E6: Total Annual MCC Budget: | H6: Rs. 26,75,000/-
A7: Opening Balance : on 1 April 2024 Cash in Hand | D7: 67601.6
A8: Cash in Bank | D8: 0
A9: Total Balance available on 1. April 2024 | D9: =D7+D8 -> 67601.6
B10: Bank interest earned | D10: 2150
A11: Grant Received from MCC for Qtr-1 2024-25: | D11: 577475 | E11: NOTE: Please add more rows if needed but make sure that the value is added to the fomula
A12: Total Balance available | D12: =SUM(D9:D11) -> 647226.6
A13: Budget ID | B13: Vendor/Expense Description | C13: MCC Approved budget-Yr-2 | D13: Quarterly Budgeted Amount Qtr-1 2024 | E13: Date | F13: Expense Amt | G13: Voucher or receipt number | H13: Budgeted Amt less Expense Amount | I13: Partner / Farmer Contribution
A14: 1 | B14: Outcome :1 Activities
A15: 1.1 | B15: Baseline | C15: 0
B17: Total 1.1 | D17: 0 | F17: =SUM(F16:F16) -> 0 | H17: =D17-F17 -> 0 | I17: =SUM(I16:I16) -> 0
A18: 1.2 | B18: Monthly PRA/ Data collection/ Village Community Meeting
A19: 1.2.1 | B19: Monthly Village Community Meeting (Biscuits / Snacks /per time /12 Months) @Rs.15 x 437 + 6 staff =Rs.6660/- | C19: 79920
B20: Being the amount paid to Jyotshnarani Pradhan prop. of New Family Bazar,Thakurmunda through NEFT Chq. No.046885 towards purchased of Biscuits for participants of 06nos Monthly village community Meeting month of April-2024. Vide Bill No.89 dtd. 04.04.2024 | E20: 09.05.2024 | F20: 6555 | G20: P.V No. 07
B21: Being the amount paid to Jyotshnarani Pradhan prop. of New Family Bazar,Thakurmunda through NEFT Chq. No.046897 towards purchased of Biscuits for participants of 06nos Monthly village community Meeting month of May-2024. Vide Bill No.157 dtd.15.05.2024 | E21: 11.06.2024 | F21: 6300 | G21: P.V No. 28
B22: Being the amount paid to Jyotshnarani Pradhan prop. of New Family Bazar,Thakurmunda through NEFT Chq. No.046907 towards purchased of Biscuits for participants of 06nos Monthly village community Meeting month of June-2024. Vide Bill No.124 dtd.04.06.2024 | E22: 29.06.2024 | F22: 6510 | G22: P.V No. 42
B23: Total 1.2.1 | D23: 19980 | F23: =SUM(F20:F22) -> 19365 | H23: =D23-F23 -> 615 | I23: =SUM(I20:I22) -> 0
B24: Activities Sub Total 1.2 | C24: =SUM(C15,C19) -> 79920 | D24: =D23+D17 -> 19980 | F24: =SUM(F23) -> 19365 | H24: =D24-F24 -> 615 | I24: =SUM(I23) -> 0
A25: 1.3 | B25: Training on Improved agriculture methods and Technology :- a) SRI (Paddy farming in row) b) Multi cropping c) Crop diversification d) Crop rotation e) Azola growing f) Seed preservation g) Seed treatment
A26: 1.3.1 | B26: Honorarium , travelling & food for resource person @Rs.2000 (above mentioned some subject will be conducted by the Project staff) | C26: 2000
B27: Being the amount paid to Jagannath Sahu through NEFT Chq. No.046890 towards Resouce person honorarium with travel for Training on improved agriculture methods and Technology. on dtd.24.05.2024 held at.DAPTA Office ,Thakurmunda. | E27: 31.05.2024 | F27: 1750 | G27: P.V No.18
B28: Being the amount paid to Narayan Barik Prop. Of Hotel Swagatika through NEFT Chq. No.046891 towards supply of Food for RP on Training on improved agriculture methods and Technology. on dtd.24.05.2024 held at.DAPTA Office ,Thakurmunda. Vide Bill No.1581 dtd.24.05.2024 | E28: 31.05.2024 | F28: 210 | G28: P.v No. 24
B30: Total 1.3.1 | D30: 2000 | F30: =SUM(F27:F29) -> 1960 | H30: =D30-F30 -> 40 | I30: =SUM(I27:I29) -> 0
A31: 1.3.2 | B31: Food for 20 participants & 6 staff @ Rs.120 x 26 Person | C31: 12480
B32: Being the amount paid to Narayan Barik Prop. Of Hotel Swagatika through NEFT Chq. No.046891 towards supply of Food for Participants on Training on Improved agriculture methods and Technology on dtd.24.05.24. Vide bill No.1582 dtd.24.05.2024 | E32: 31.05.2024 | F32: 3120 | G32: P.V No.22
B35: Total 1.3.2 | D35: 3120 | F35: =SUM(F32:F34) -> 3120 | H35: =D35-F35 -> 0 | I35: =SUM(I32:I34) -> 0
A36: 1.3.3 | B36: Project village to training venue Transportation charges 20 participants x 1 Project villages @ Rs.2500/-; 2 vehicles | C36: 20000
B37: Being the amount paid to Ramasingh Badra,Prop. of Badra Tour & Travel through NEFT Chq. No.046890 towards hiring of 2no of vehicle for participants transportation on Training on Improved agriculture methods and Technology on dtd.24.05.24 held at.DAPTA,Thakurmunda Vide Bill No.92, 93 dtd.24.05.2024 | E37: 31.05.2024 | F37: 5000 | G37: P.V. No.20
B39: Total 1.3.3 | D39: 5000 | F39: =SUM(F37:F38) -> 5000 | H39: =D39-F39 -> 0 | I39: =SUM(I37:I38) -> 0
A40: 1.3.4 | B40: Arrangements & training matterials @ Rs.500/- | C40: 2000
B41: Being the amount paid to Baigyanik Mohanta, Prop. of Gayatree Book Store through NEFT Chq. No.046891 towards Training Materials for Participants on Training on Improved agriculture methods and Technology on dtd.24.05.24 held at.DAPTA,Thakurmunda Vide Bill No.219 dtd.24.05.2024 | E41: 31.05.2024 | F41: 500 | G41: P.V No.23
B43: Total 1.3.4 | D43: 500 | F43: =SUM(F41:F42) -> 500 | H43: =D43-F43 -> 0 | I43: =SUM(I41:I42) -> 0
B44: Activities Sub Total 1.3 | C44: =SUM(C26:C40) -> 36480 | D44: =SUM(D43,D39,D35,D30) -> 10620 | F44: =SUM(F43,F39,F35,F30) -> 10580 | H44: =D44-F44 -> 40 | I44: =SUM(I43,I39,I35,I30) -> 0
A45: 1.4 | B45: Training on Natural Resource Management a) Soil health ( Testing, treatment and preservation) b) Organic farming (Chemical free) c) Compost pit & its preparation d) Vermin compost making e) Bio- Pesticide f) Bio- fertilizer
A46: 1.4.1 | B46: Honorarium, travelling & food for resource person @Rs.2000 | C46: 8000
...

Sheet  Qtr- 2 July-24 to Sept-24  (2)
B1: Partner: DAPTA (Development Agency for Poor and Tribal Awakening)
A2: Quarterly/Monthly Reporting Format
A3: Ensuring food and livelihood security of indigenous and other marginalized communities in Thakurmunda Block, Mayurbhanj, Odisha
D4: Accounting Period: | E4: Start: 1 July 2024
E5: End: 30 Sept 2024
A6: Date: Grant received on | D6: 16.07.2024 | E6: Total Annual MCC Budget: | H6: =+' Qtr-1 April-24 to June-24 '!H6:I6 -> Rs. 26,75,000/-
A7: Opening Balalnce : on 1 July 2024 Cash in Cash | D7: 111252.22
A8: Cash in Bank | D8: 0
A9: Total Balance available on 1.July 2024 | D9: =D8+D7 -> 111252.22
A10: Bank interest earned | D10: 2994
A11: Grant Received from MCC for Qtr-2 2024-25: | D11: 720885 | E11: NOTE: Please add more rows if needed but make sure that the value is added to the fomula
A12: Total Balance available | D12: =SUM(D9:D11) -> 835131.22
A13: Budget ID | B13: Vendor/Expense Description | C13: MCC Approved budget-Yr-1 | D13: Quarterly Budgeted Amount Qtr-2 2024 | E13: Date | F13: Expense Amt | G13: Voucher or receipt number | H13: Budgeted Amt less Expense Amount | I13: Partner / Farmer Contribution
A14: 1 | B14: Outcome :1 Activities
A15: 1.1 | B15: Baseline | C15: 0
B17: Total 1.1 | D17: 0 | F17: =SUM(F16:F16) -> 0 | H17: =D17-F17 -> 0
A18: 1.2 | B18: Monthly PRA/ Data collection/ Village Community Meeting
A19: 1.2.1 | B19: Monthly Village Community Meeting (Biscuits / Snacks /per time /12 Months) @Rs.15 x 437 + 6 staff =Rs.6660/- | C19: 79920
B20: Being the amount paid to Jyotshnarani Pradhan prop. of New Family Bazar,Thakurmunda through NEFT Chq. No.046916 towards purchased of Biscuits for participants of 06nos Monthly village community Meeting month of July-2024. vide Bill No. 176 dtd.02.07.24. | E20: 31.07.24 | F20: 6480 | G20: P.V No.52
B21: Being the amount paid to Lizarani Barik prop. of Lijarani Traders,Thakurmunda through NEFT Chq. No.046930 towards purchased of Biscuits for participants of 06nos Monthly village community Meeting month of Aug-2024. Vide Bill No.055 dtd.02.08.2024 | E21: 30.08.2024 | F21: 5100 | G21: P.V No.64
B22: Being the amount paid to Lijarani Barik prop. of Lijarani Traders,Thakurmunda through NEFT Chq. No.046943 towards purchased of Biscuits for participants of 06nos Monthly village community Meeting month of Sept-2024.Vide Bill No.064 dtd.3.09.2024 | E22: 30.09.24 | F22: 6000 | G22: P.V No.77
B23: Total 1.2.1 | D23: 19980 | F23: =SUM(F20:F22) -> 17580 | H23: =D23-F23 -> 2400
B24: Activities Sub Total 1.2 | C24: =SUM(C15,C19) -> 79920 | D24: =D23+D17 -> 19980 | F24: =SUM(F23) -> 17580 | H24: =D24-F24 -> 2400 | I24: =SUM(I15,I19) -> 0
A25: 1.3 | B25: Training on Improved agriculture methods and Technology :- a) SRI (Paddy farming in row) b) Multi cropping c) Crop diversification d) Crop rotation e) Azola growing f) Seed preservation g) Seed treatment
A26: 1.3.1 | B26: Honorarium , travelling & food for resource person @Rs.2000 (above mentioned some subject will be conducted by the Project staff) | C26: 2000
B28: Total 1.3.1 | D28: 0 | F28: =SUM(F27:F27) -> 0 | H28: =D28-F28 -> 0
A29: 1.3.2 | B29: Food for 20 participants & 6 staff @ Rs.120 x 26 Person | C29: 12480
B31: Total 1.3.2 | D31: 3120 | F31: =SUM(F30:F30) -> 0 | H31: =D31-F31 -> 3120
A32: 1.3.3 | B32: Project village to training venue Transportation charges 20 participants x 1 Project villages @ Rs.2500/-; 2 vehicles | C32: 20000
B34: Total 1.3.3 | D34: 5000 | F34: =SUM(F33:F33) -> 0 | H34: =D34-F34 -> 5000
A35: 1.3.4 | B35: Arrangements & training matterials @ Rs.500/- | C35: 2000
B37: Total 1.3.4 | D37: 500 | F37: =SUM(F36:F36) -> 0 | H37: =D37-F37 -> 500
B38: Activities Sub Total 1.3 | C38: =SUM(C26:C35) -> 36480 | D38: =SUM(D37,D34,D31,D28) -> 8620 | F38: =SUM(F37,F34,F31,F28) -> 0 | H38: =D38-F38 -> 8620
A39: 1.4 | B39: Training on Natural Resource Management a) Soil health ( Testing, treatment and preservation) b) Organic farming (Chemical free) c) Compost pit & its preparation d) Vermin compost making e) Bio- Pesticide f) Bio- fertilizer
A40: 1.4.1 | B40: Honorarium, travelling & food for resource person @Rs.2000 | C40: 8000
B41: Being the amount paid to Narayan Barik, Prop of. Hotel Swagatika through NEFT Chq. No.04687 towards supply of food for Resource Person on Natural resource management Training dtd.13.08.2024 held at DAPTA,Thakurmunda. Vide Bill No.1698 dtd.13.08.24 | E41: 22.08.24 | F41: 180 | G41: P.V No.60
B42: Being the amount paid to Jagannath Sahu through NEFT Chq. No.046925 towards Resouce person honorarium with travel on Natural resource management training dtd.13.08.24 held at.DAPTA Office ,Thakurmunda. | E42: 22.08.24 | F42: 1750 | G42: P.V No.61
B43: Total 1.4.1 | D43: 2000 | F43: =SUM(F41:F42) -> 1930 | H43: =D43-F43 -> 70
A44: 1.4.2 | B44: Food for 35 participants form 7 project located villages each village 5 participants & 6 staff @ Rs.120 x 41 Person =Rs.3360 | C44: 19680
B45: Being the amount paid to Narayan Barik, Prop of. Hotel Swagatika through NEFT Chq. No.04687 towards supply of food for participants on Natural resource management Training dtd.13.08.2024 held at DAPTA,Thakurmunda. Vide Bill No.1697 dtd.13.08.24 | E45: 22.08.24 | F45: 4680 | G45: P.V No.60
...

Sheet  Qtr-3 Octo-24 to Dec-24
B1: Partner: DAPTA (Development Agency for Poor and Tribal Awakening)
A2: Quarterly/Monthly Reporting Format
A3: Ensuring food and livelihood security of indigenous and other marginalized communities in Thakurmunda Block, Mayurbhanj, Odisha
D4: Accounting Period: | E4: Start: 1 Octo. 2024
E5: End: 31 Dec. 2024
A6: Date: Grant received on | D6: 15.10.2024 | E6: Total Annual MCC Budget: | H6: =+' Qtr-1 April-24 to June-24 '!H6:I6 -> Rs. 26,75,000/-
A7: Opening Balalnce : on 1 Octo. 2024 Cash in Hand | D7: 0
A8: Cash in Bank | D8: 70766.32
A9: Total Balance available on 1.Octo. 2024 | D9: =D8+D7 -> 70766.32
A10: Bank interest earned | D10: 2912
A11: Grant Received from MCC for Qtr-3 2024-25: | D11: 526803 | E11: NOTE: Please add more rows if needed but make sure that the value is added to the fomula
A12: Total Balance available | D12: =SUM(D9:D11) -> 600481.32
A13: Budget ID | B13: Vendor/Expense Description | C13: MCC Approved budget-Yr-1 | D13: Quarterly Budgeted Amount Qtr-3 2024 | E13: Date | F13: Expense Amt | G13: Voucher or receipt number | H13: Budgeted Amt less Expense Amount | I13: Partner / Farmer Contribution
A14: 1 | B14: Outcome :1 Activities
A15: 1.1 | B15: Baseline | C15: 0
B18: Total 1.1 | D18: 0 | F18: =SUM(F16:F17) -> 0 | H18: =D18-F18 -> 0 | I18: =SUM(I16:I17) -> 0
A19: 1.2 | B19: Monthly PRA/ Data collection/ Village Community Meeting
A20: 1.2.1 | B20: Monthly Village Community Meeting (Biscuits / Snacks /per time /12 Months) @Rs.15 x 437 + 6 staff =Rs.6660/- | C20: 79920
B21: Being the amount paid to Lijarani Barik prop. of Lijarani Traders,Thakurmunda through NEFT Chq. No.052134 towards purchased of Biscuits for participants of 06nos Monthly village community Meeting month of October-2024. Vide Bill No.066 dtd.30.10.2024 | E21: 04.11.2024 | F21: 6000 | G21: Pv. No.101
B22: Being the amount paid to Lijarani Barik prop. of Lijarani Traders,Thakurmunda through NEFT Chq. No.052150 towards purchased of Biscuits for participants of 06nos Monthly village community Meeting month of November-2024. Vide Bill No. 071 dtd. 02.11.2024 | E22: 30.11.2024 | F22: 6435 | G22: Pv. No.117
B23: Being the amount paid to Lijarani Barik prop. of Lijarani Traders,Thakurmunda through NEFT Chq. No.052064 towards purchased of Biscuits for participants of 06nos Monthly village community Meeting month of Dec-2024. Vide Bill No. 073 dtd. 30.12.2024 | E23: 30.12.2024 | F23: 6300 | G23: Pv. No.134
B24: Total 1.2.1 | D24: 19980 | F24: =SUM(F21:F23) -> 18735 | H24: =D24-F24 -> 1245 | I24: =SUM(I21:I23) -> 0
B25: Activities Sub Total 1.2 | C25: =SUM(C15,C20) -> 79920 | D25: =D24+D18 -> 19980 | F25: =SUM(F24) -> 18735 | H25: =D25-F25 -> 1245 | I25: =SUM(I24) -> 0
A26: 1.3 | B26: Training on Improved agriculture methods and Technology :- a) SRI (Paddy farming in row) b) Multi cropping c) Crop diversification d) Crop rotation e) Azola growing f) Seed preservation g) Seed treatment
A27: 1.3.1 | B27: Honorarium , travelling & food for resource person @Rs.2000 (above mentioned some subject will be conducted by the Project staff) | C27: 2000
B31: Total 1.3.1 | F31: =SUM(F28:F30) -> 0 | H31: =D31-F31 -> 0
A32: 1.3.2 | B32: Food for 20 participants & 6 staff @ Rs.120 x 26 Person | C32: 12480
B33: Being the amount paid to Narayan Barik Prop. Of . Hotel Swagatika through NEFT Chq. No.052142 towards supply of Food for Participants on Improved agriculture Methods & Technology Training on dtd.13.11.2024 held at. DAPTA Office, Thakurmunda. Vide Bill No. 1748 dtd.13.11.2024 | E33: 14.11.2024 | F33: 3000 | G33: Pv. No.112
B34: Being the amount paid to Narayan Barik Prop. Of .Hotel Swagatika through NEFT Chq. No.052055 towards supply of Food for Participants on Improved agriculture Methods & Technology Training on dtd.29.11.2024 held at. DAPTA Office, Thakurmunda Vide Bill No.1754 dtd. 29.11.2024. | E34: 09.12.2024 | F34: 3120 | G34: Pv. No.124
B36: Total 1.3.2 | D36: 3120 | F36: =SUM(F33:F35) -> 6120 | H36: =D36-F36 -> -3000 | I36: =SUM(I33:I35) -> 0
A37: 1.3.3 | B37: Project village to training venue Transportation charges 20 participants x 1 Project villages @ Rs.2500/-; 2 vehicles | C37: 20000
B38: Being the amount paid to Ramasingh Badra, Prop. Of badra Tour & travel through NEFT Chq. No.052143 towards hiring of 2no of vehicle for transportation on Improved agriculture Agriculture methods & Technology on dtd.13.11.24 held at. DAPTA Office, Thakurmunda.142 & 143 dtd. 13.11.2024. | E38: 14.11.2024 | F38: 5000 | G38: Pv. No.114
B39: Being the amount paid toRamasingh Badra Prop. of Badra tour & travel through NEFT Chq. No.052024 towards Hiring 2nos of Vehicle for Participants on r Trng on Improved Agriculture dtd.29.11.24. held at. DAPTA office, Thakurmunda. Vide Bill No.150& 151 dtd. 29.11.2024. | E39: 09.12.2024 | F39: 5000 | G39: Pv. No.121
B41: Total 1.3.3 | D41: 5000 | F41: =SUM(F38:F40) -> 10000 | H41: =D41-F41 -> -5000 | I41: =SUM(I38:I40) -> 0
A42: 1.3.4 | B42: Arrangements & training matterials @ Rs.500/- | C42: 2000
B43: Being the amount paid to Baigyanik Mohanta Prop. Of Gayatree Book Store through NEFT Chq. No.052142 towards purchased of Training Materials for Participants on Improved agriculture Agriculture Methods & Technology Training dtd.13.11.24 held at. DAPTA Office, Thakurmunda. Vide Bill no. 273 dtd. 13.11.2024 | E43: 14.11.2024 | F43: 400 | G43: Pv. No.113
B44: Being the amount paid to Baigyanik Mohanta Prop. Of Gayatree Book Store through NEFT Chq. No.052055 towards purchased of Training Materials for Participants on Improved agriculture Agriculture Methods & Technology Training dtd.29.11.2024 held at. DAPTA Office, Thakurmunda. Vide Bill No.281 dtd. 29.11.2024. | E44: 09.12.2024 | F44: 500 | G44: Pv. No.123
B45: Total 1.3.4 | D45: 500 | F45: =SUM(F43:F44) -> 900 | H45: =D45-F45 -> -400 | I45: =SUM(I43:I44) -> 0
B46: Activities Sub Total 1.3 | C46: =SUM(C27:C42) -> 36480 | D46: =SUM(D45,D41,D36,D31) -> 8620 | F46: =SUM(F45,F41,F36,F31) -> 17020 | H46: =D46-F46 -> -8400 | I46: =SUM(I45,I41,I36,I31) -> 0
A47: 1.4 | B47: Training on Natural Resource Management a) Soil health ( Testing, treatment and preservation) b) Organic farming (Chemical free) c) Compost pit & its preparation d) Vermin compost making e) Bio- Pesticide f) Bio- fertilizer
...

Sheet  Qtr-4 Jan-25 to march-25
B1: Partner: DAPTA (Development Agency for Poor and Tribal Awakening)
A2: Quarterly/Monthly Reporting Format
A3: Ensuring food and livelihood security of indigenous and other marginalized communities in Thakurmunda Block, Mayurbhanj, Odisha
D4: Accounting Period: | E4: Start: 1 Jan. 2025
E5: End: 30 March 2025
A6: Date: Grant received on | D6: 0 | E6: Total Annual MCC Budget: | H6: =+' Qtr-1 April-24 to June-24 '!H6:I6 -> Rs. 26,75,000/-
A7: Opening Balalnce : on 1 Jan. 2025 Cash in Hand | D7: 0
A8: Bank interest | D8: 0
A9: Total Balance available on 1. Jan 2025 | D9: =D7+D8 -> 0
A10: Grant Received from MCC for Qtr-2 2024-25: | E10: NOTE: Please add more rows if needed but make sure that the value is added to the fomula
A11: Total Balance available | D11: =SUM(D8:D10) -> 0
A12: Budget ID | B12: Vendor/Expense Description | C12: MCC Approved budget-Yr-1 | D12: Quarterly Budgeted Amount Qtr-4 2025 | E12: Date | F12: Expense Amt | G12: Voucher or receipt number | H12: Budgeted Amt less Expense Amount | I12: Partner / Farmer Contribution
A13: 1 | B13: Outcome :1 Activities
A14: 1.1 | B14: Baseline | C14: 0
B16: Total 1.1 | D16: 0 | F16: =SUM(F15:F15) -> 0 | H16: =D16-F16 -> 0
A17: 1.2 | B17: Monthly PRA/ Data collection/ Village Community Meeting
A18: 1.2.1 | B18: Monthly Village Community Meeting (Biscuits / Snacks /per time /12 Months) @Rs.15 x 437 + 6 staff =Rs.6660/- | C18: 79920
B21: Total 1.2.1 | D21: 19980 | F21: =SUM(F19:F20) -> 0 | H21: =D21-F21 -> 19980
B22: Activities Sub Total 1.2 | C22: =SUM(C14,C18) -> 79920 | D22: =D21+D16 -> 19980 | F22: =SUM(F21) -> 0 | H22: =D22-F22 -> 19980 | I22: =SUM(I14,I18) -> 0
A23: 1.3 | B23: Training on Improved agriculture methods and Technology :- a) SRI (Paddy farming in row) b) Multi cropping c) Crop diversification d) Crop rotation e) Azola growing f) Seed preservation g) Seed treatment
A24: 1.3.1 | B24: Honorarium , travelling & food for resource person @Rs.2000 (above mentioned some subject will be conducted by the Project staff) | C24: 2000
B28: Total 1.3.1 | D28: 2000 | F28: =SUM(F25:F27) -> 0 | H28: =D28-F28 -> 2000
A29: 1.3.2 | B29: Food for 20 participants & 6 staff @ Rs.120 x 26 Person | C29: 12480
B33: Total 1.3.2 | D33: 3120 | F33: =SUM(F30:F32) -> 0 | H33: =D33-F33 -> 3120
A34: 1.3.3 | B34: Project village to training venue Transportation charges 20 participants x 1 Project villages @ Rs.2500/-; 2 vehicles | C34: 20000
B37: Total 1.3.3 | D37: 5000 | F37: =SUM(F35:F36) -> 0 | H37: =D37-F37 -> 5000
A38: 1.3.4 | B38: Arrangements & training matterials @ Rs.500/- | C38: 2000
B41: Total 1.3.4 | D41: 500 | F41: =SUM(F39:F40) -> 0 | H41: =D41-F41 -> 500
B42: Activities Sub Total 1.3 | C42: =SUM(C24:C38) -> 36480 | D42: =SUM(D41,D37,D33,D28) -> 10620 | F42: =SUM(F41,F37,F33,F28) -> 0 | H42: =D42-F42 -> 10620
A43: 1.4 | B43: Training on Natural Resource Management a) Soil health ( Testing, treatment and preservation) b) Organic farming (Chemical free) c) Compost pit & its preparation d) Vermin compost making e) Bio- Pesticide f) Bio- fertilizer
A44: 1.4.1 | B44: Honorarium, travelling & food for resource person @Rs.2000 | C44: 8000
B46: Total 1.4.1 | D46: 2000 | F46: =F45 -> 0 | H46: =D46-F46 -> 2000
A47: 1.4.2 | B47: Food for 35 participants form 7 project located villages each village 5 participants & 6 staff @ Rs.120 x 41 Person =Rs.3360 | C47: 19680
B50: Total 1.4.2 | D50: 4920 | F50: =SUM(F48:F49) -> 0 | H50: =D50-F50 -> 4920
A51: 1.4.3 | B51: Project village to training venue transportation charges Rs.7500/- each village 5 participants x 7 Project villges 3 vehicles for 2 trainings | C51: 30000
B54: Total 1.4.3 | D54: 7500 | F54: =SUM(F52:F53) -> 0 | H54: =D54-F54 -> 7500
A55: 1.4.4 | B55: Arrangements & training matterials @ Rs.500/- | C55: 2000
B58: Total 1.4.4 | D58: 500 | F58: =SUM(F56:F57) -> 0 | H58: =D58-F58 -> 500
B59: Activities Sub Total 1.4 | C59: =SUM(C44:C55) -> 59680 | D59: =SUM(D58,D54,D50,D46) -> 14920 | F59: =SUM(F58,F54,F50,F46) -> 0 | H59: =D59-F59 -> 14920
A60: 1.5 | B60: Pulses Seeds (Horse gram & Black gram) distribution
...
